
2019-09-22 07:32:39,417 INFO: errors [in /Users/SanchitBatra/Desktop/Projects/deploybrh/app.py:263]
2019-09-22 07:32:46,091 ERROR: Exception on /favicon.ico [GET] [in /Users/SanchitBatra/Desktop/Projects/deploybrh/venv/lib/python3.7/site-packages/flask/app.py:1891]
Traceback (most recent call last):
  File "/Users/SanchitBatra/Desktop/Projects/deploybrh/venv/lib/python3.7/site-packages/flask/app.py", line 1949, in full_dispatch_request
    rv = self.dispatch_request()
  File "/Users/SanchitBatra/Desktop/Projects/deploybrh/venv/lib/python3.7/site-packages/flask/app.py", line 1925, in dispatch_request
    self.raise_routing_exception(req)
  File "/Users/SanchitBatra/Desktop/Projects/deploybrh/venv/lib/python3.7/site-packages/flask/app.py", line 1907, in raise_routing_exception
    raise request.routing_exception
  File "/Users/SanchitBatra/Desktop/Projects/deploybrh/venv/lib/python3.7/site-packages/flask/ctx.py", line 350, in match_request
    result = self.url_adapter.match(return_rule=True)
  File "/Users/SanchitBatra/Desktop/Projects/deploybrh/venv/lib/python3.7/site-packages/werkzeug/routing.py", line 1799, in match
    raise NotFound()
werkzeug.exceptions.NotFound: 404 Not Found: The requested URL was not found on the server. If you entered the URL manually please check your spelling and try again.

During handling of the above exception, another exception occurred:

Traceback (most recent call last):
  File "/Users/SanchitBatra/Desktop/Projects/deploybrh/venv/lib/python3.7/site-packages/flask/app.py", line 2446, in wsgi_app
    response = self.full_dispatch_request()
  File "/Users/SanchitBatra/Desktop/Projects/deploybrh/venv/lib/python3.7/site-packages/flask/app.py", line 1951, in full_dispatch_request
    rv = self.handle_user_exception(e)
  File "/Users/SanchitBatra/Desktop/Projects/deploybrh/venv/lib/python3.7/site-packages/flask/app.py", line 1815, in handle_user_exception
    return self.handle_http_exception(e)
  File "/Users/SanchitBatra/Desktop/Projects/deploybrh/venv/lib/python3.7/site-packages/flask/app.py", line 1743, in handle_http_exception
    return handler(e)
  File "/Users/SanchitBatra/Desktop/Projects/deploybrh/app.py", line 251, in not_found_error
    return render_template('errors/404.html'), 404
  File "/Users/SanchitBatra/Desktop/Projects/deploybrh/venv/lib/python3.7/site-packages/flask/templating.py", line 138, in render_template
    ctx.app.jinja_env.get_or_select_template(template_name_or_list),
  File "/Users/SanchitBatra/Desktop/Projects/deploybrh/venv/lib/python3.7/site-packages/jinja2/environment.py", line 869, in get_or_select_template
    return self.get_template(template_name_or_list, parent, globals)
  File "/Users/SanchitBatra/Desktop/Projects/deploybrh/venv/lib/python3.7/site-packages/jinja2/environment.py", line 830, in get_template
    return self._load_template(name, self.make_globals(globals))
  File "/Users/SanchitBatra/Desktop/Projects/deploybrh/venv/lib/python3.7/site-packages/jinja2/environment.py", line 804, in _load_template
    template = self.loader.load(self, name, globals)
  File "/Users/SanchitBatra/Desktop/Projects/deploybrh/venv/lib/python3.7/site-packages/jinja2/loaders.py", line 113, in load
    source, filename, uptodate = self.get_source(environment, name)
  File "/Users/SanchitBatra/Desktop/Projects/deploybrh/venv/lib/python3.7/site-packages/flask/templating.py", line 60, in get_source
    return self._get_source_fast(environment, template)
  File "/Users/SanchitBatra/Desktop/Projects/deploybrh/venv/lib/python3.7/site-packages/flask/templating.py", line 89, in _get_source_fast
    raise TemplateNotFound(template)
jinja2.exceptions.TemplateNotFound: errors/404.html
2019-09-22 07:32:57,735 ERROR: Exception on /favicon.ico [GET] [in /Users/SanchitBatra/Desktop/Projects/deploybrh/venv/lib/python3.7/site-packages/flask/app.py:1891]
Traceback (most recent call last):
  File "/Users/SanchitBatra/Desktop/Projects/deploybrh/venv/lib/python3.7/site-packages/flask/app.py", line 1949, in full_dispatch_request
    rv = self.dispatch_request()
  File "/Users/SanchitBatra/Desktop/Projects/deploybrh/venv/lib/python3.7/site-packages/flask/app.py", line 1925, in dispatch_request
    self.raise_routing_exception(req)
  File "/Users/SanchitBatra/Desktop/Projects/deploybrh/venv/lib/python3.7/site-packages/flask/app.py", line 1907, in raise_routing_exception
    raise request.routing_exception
  File "/Users/SanchitBatra/Desktop/Projects/deploybrh/venv/lib/python3.7/site-packages/flask/ctx.py", line 350, in match_request
    result = self.url_adapter.match(return_rule=True)
  File "/Users/SanchitBatra/Desktop/Projects/deploybrh/venv/lib/python3.7/site-packages/werkzeug/routing.py", line 1799, in match
    raise NotFound()
werkzeug.exceptions.NotFound: 404 Not Found: The requested URL was not found on the server. If you entered the URL manually please check your spelling and try again.

During handling of the above exception, another exception occurred:

Traceback (most recent call last):
  File "/Users/SanchitBatra/Desktop/Projects/deploybrh/venv/lib/python3.7/site-packages/flask/app.py", line 2446, in wsgi_app
    response = self.full_dispatch_request()
  File "/Users/SanchitBatra/Desktop/Projects/deploybrh/venv/lib/python3.7/site-packages/flask/app.py", line 1951, in full_dispatch_request
    rv = self.handle_user_exception(e)
  File "/Users/SanchitBatra/Desktop/Projects/deploybrh/venv/lib/python3.7/site-packages/flask/app.py", line 1815, in handle_user_exception
    return self.handle_http_exception(e)
  File "/Users/SanchitBatra/Desktop/Projects/deploybrh/venv/lib/python3.7/site-packages/flask/app.py", line 1743, in handle_http_exception
    return handler(e)
  File "/Users/SanchitBatra/Desktop/Projects/deploybrh/app.py", line 251, in not_found_error
    return render_template('errors/404.html'), 404
  File "/Users/SanchitBatra/Desktop/Projects/deploybrh/venv/lib/python3.7/site-packages/flask/templating.py", line 138, in render_template
    ctx.app.jinja_env.get_or_select_template(template_name_or_list),
  File "/Users/SanchitBatra/Desktop/Projects/deploybrh/venv/lib/python3.7/site-packages/jinja2/environment.py", line 869, in get_or_select_template
    return self.get_template(template_name_or_list, parent, globals)
  File "/Users/SanchitBatra/Desktop/Projects/deploybrh/venv/lib/python3.7/site-packages/jinja2/environment.py", line 830, in get_template
    return self._load_template(name, self.make_globals(globals))
  File "/Users/SanchitBatra/Desktop/Projects/deploybrh/venv/lib/python3.7/site-packages/jinja2/environment.py", line 804, in _load_template
    template = self.loader.load(self, name, globals)
  File "/Users/SanchitBatra/Desktop/Projects/deploybrh/venv/lib/python3.7/site-packages/jinja2/loaders.py", line 113, in load
    source, filename, uptodate = self.get_source(environment, name)
  File "/Users/SanchitBatra/Desktop/Projects/deploybrh/venv/lib/python3.7/site-packages/flask/templating.py", line 60, in get_source
    return self._get_source_fast(environment, template)
  File "/Users/SanchitBatra/Desktop/Projects/deploybrh/venv/lib/python3.7/site-packages/flask/templating.py", line 89, in _get_source_fast
    raise TemplateNotFound(template)
jinja2.exceptions.TemplateNotFound: errors/404.html
2019-09-22 07:33:01,383 ERROR: Exception on /favicon.ico [GET] [in /Users/SanchitBatra/Desktop/Projects/deploybrh/venv/lib/python3.7/site-packages/flask/app.py:1891]
Traceback (most recent call last):
  File "/Users/SanchitBatra/Desktop/Projects/deploybrh/venv/lib/python3.7/site-packages/flask/app.py", line 1949, in full_dispatch_request
    rv = self.dispatch_request()
  File "/Users/SanchitBatra/Desktop/Projects/deploybrh/venv/lib/python3.7/site-packages/flask/app.py", line 1925, in dispatch_request
    self.raise_routing_exception(req)
  File "/Users/SanchitBatra/Desktop/Projects/deploybrh/venv/lib/python3.7/site-packages/flask/app.py", line 1907, in raise_routing_exception
    raise request.routing_exception
  File "/Users/SanchitBatra/Desktop/Projects/deploybrh/venv/lib/python3.7/site-packages/flask/ctx.py", line 350, in match_request
    result = self.url_adapter.match(return_rule=True)
  File "/Users/SanchitBatra/Desktop/Projects/deploybrh/venv/lib/python3.7/site-packages/werkzeug/routing.py", line 1799, in match
    raise NotFound()
werkzeug.exceptions.NotFound: 404 Not Found: The requested URL was not found on the server. If you entered the URL manually please check your spelling and try again.

During handling of the above exception, another exception occurred:

Traceback (most recent call last):
  File "/Users/SanchitBatra/Desktop/Projects/deploybrh/venv/lib/python3.7/site-packages/flask/app.py", line 2446, in wsgi_app
    response = self.full_dispatch_request()
  File "/Users/SanchitBatra/Desktop/Projects/deploybrh/venv/lib/python3.7/site-packages/flask/app.py", line 1951, in full_dispatch_request
    rv = self.handle_user_exception(e)
  File "/Users/SanchitBatra/Desktop/Projects/deploybrh/venv/lib/python3.7/site-packages/flask/app.py", line 1815, in handle_user_exception
    return self.handle_http_exception(e)
  File "/Users/SanchitBatra/Desktop/Projects/deploybrh/venv/lib/python3.7/site-packages/flask/app.py", line 1743, in handle_http_exception
    return handler(e)
  File "/Users/SanchitBatra/Desktop/Projects/deploybrh/app.py", line 251, in not_found_error
    return render_template('errors/404.html'), 404
  File "/Users/SanchitBatra/Desktop/Projects/deploybrh/venv/lib/python3.7/site-packages/flask/templating.py", line 138, in render_template
    ctx.app.jinja_env.get_or_select_template(template_name_or_list),
  File "/Users/SanchitBatra/Desktop/Projects/deploybrh/venv/lib/python3.7/site-packages/jinja2/environment.py", line 869, in get_or_select_template
    return self.get_template(template_name_or_list, parent, globals)
  File "/Users/SanchitBatra/Desktop/Projects/deploybrh/venv/lib/python3.7/site-packages/jinja2/environment.py", line 830, in get_template
    return self._load_template(name, self.make_globals(globals))
  File "/Users/SanchitBatra/Desktop/Projects/deploybrh/venv/lib/python3.7/site-packages/jinja2/environment.py", line 804, in _load_template
    template = self.loader.load(self, name, globals)
  File "/Users/SanchitBatra/Desktop/Projects/deploybrh/venv/lib/python3.7/site-packages/jinja2/loaders.py", line 113, in load
    source, filename, uptodate = self.get_source(environment, name)
  File "/Users/SanchitBatra/Desktop/Projects/deploybrh/venv/lib/python3.7/site-packages/flask/templating.py", line 60, in get_source
    return self._get_source_fast(environment, template)
  File "/Users/SanchitBatra/Desktop/Projects/deploybrh/venv/lib/python3.7/site-packages/flask/templating.py", line 89, in _get_source_fast
    raise TemplateNotFound(template)
jinja2.exceptions.TemplateNotFound: errors/404.html
2019-09-22 07:33:03,265 ERROR: Exception on /favicon.ico [GET] [in /Users/SanchitBatra/Desktop/Projects/deploybrh/venv/lib/python3.7/site-packages/flask/app.py:1891]
Traceback (most recent call last):
  File "/Users/SanchitBatra/Desktop/Projects/deploybrh/venv/lib/python3.7/site-packages/flask/app.py", line 1949, in full_dispatch_request
    rv = self.dispatch_request()
  File "/Users/SanchitBatra/Desktop/Projects/deploybrh/venv/lib/python3.7/site-packages/flask/app.py", line 1925, in dispatch_request
    self.raise_routing_exception(req)
  File "/Users/SanchitBatra/Desktop/Projects/deploybrh/venv/lib/python3.7/site-packages/flask/app.py", line 1907, in raise_routing_exception
    raise request.routing_exception
  File "/Users/SanchitBatra/Desktop/Projects/deploybrh/venv/lib/python3.7/site-packages/flask/ctx.py", line 350, in match_request
    result = self.url_adapter.match(return_rule=True)
  File "/Users/SanchitBatra/Desktop/Projects/deploybrh/venv/lib/python3.7/site-packages/werkzeug/routing.py", line 1799, in match
    raise NotFound()
werkzeug.exceptions.NotFound: 404 Not Found: The requested URL was not found on the server. If you entered the URL manually please check your spelling and try again.

During handling of the above exception, another exception occurred:

Traceback (most recent call last):
  File "/Users/SanchitBatra/Desktop/Projects/deploybrh/venv/lib/python3.7/site-packages/flask/app.py", line 2446, in wsgi_app
    response = self.full_dispatch_request()
  File "/Users/SanchitBatra/Desktop/Projects/deploybrh/venv/lib/python3.7/site-packages/flask/app.py", line 1951, in full_dispatch_request
    rv = self.handle_user_exception(e)
  File "/Users/SanchitBatra/Desktop/Projects/deploybrh/venv/lib/python3.7/site-packages/flask/app.py", line 1815, in handle_user_exception
    return self.handle_http_exception(e)
  File "/Users/SanchitBatra/Desktop/Projects/deploybrh/venv/lib/python3.7/site-packages/flask/app.py", line 1743, in handle_http_exception
    return handler(e)
  File "/Users/SanchitBatra/Desktop/Projects/deploybrh/app.py", line 251, in not_found_error
    return render_template('errors/404.html'), 404
  File "/Users/SanchitBatra/Desktop/Projects/deploybrh/venv/lib/python3.7/site-packages/flask/templating.py", line 138, in render_template
    ctx.app.jinja_env.get_or_select_template(template_name_or_list),
  File "/Users/SanchitBatra/Desktop/Projects/deploybrh/venv/lib/python3.7/site-packages/jinja2/environment.py", line 869, in get_or_select_template
    return self.get_template(template_name_or_list, parent, globals)
  File "/Users/SanchitBatra/Desktop/Projects/deploybrh/venv/lib/python3.7/site-packages/jinja2/environment.py", line 830, in get_template
    return self._load_template(name, self.make_globals(globals))
  File "/Users/SanchitBatra/Desktop/Projects/deploybrh/venv/lib/python3.7/site-packages/jinja2/environment.py", line 804, in _load_template
    template = self.loader.load(self, name, globals)
  File "/Users/SanchitBatra/Desktop/Projects/deploybrh/venv/lib/python3.7/site-packages/jinja2/loaders.py", line 113, in load
    source, filename, uptodate = self.get_source(environment, name)
  File "/Users/SanchitBatra/Desktop/Projects/deploybrh/venv/lib/python3.7/site-packages/flask/templating.py", line 60, in get_source
    return self._get_source_fast(environment, template)
  File "/Users/SanchitBatra/Desktop/Projects/deploybrh/venv/lib/python3.7/site-packages/flask/templating.py", line 89, in _get_source_fast
    raise TemplateNotFound(template)
jinja2.exceptions.TemplateNotFound: errors/404.html
2019-09-22 07:33:05,245 ERROR: Exception on /favicon.ico [GET] [in /Users/SanchitBatra/Desktop/Projects/deploybrh/venv/lib/python3.7/site-packages/flask/app.py:1891]
Traceback (most recent call last):
  File "/Users/SanchitBatra/Desktop/Projects/deploybrh/venv/lib/python3.7/site-packages/flask/app.py", line 1949, in full_dispatch_request
    rv = self.dispatch_request()
  File "/Users/SanchitBatra/Desktop/Projects/deploybrh/venv/lib/python3.7/site-packages/flask/app.py", line 1925, in dispatch_request
    self.raise_routing_exception(req)
  File "/Users/SanchitBatra/Desktop/Projects/deploybrh/venv/lib/python3.7/site-packages/flask/app.py", line 1907, in raise_routing_exception
    raise request.routing_exception
  File "/Users/SanchitBatra/Desktop/Projects/deploybrh/venv/lib/python3.7/site-packages/flask/ctx.py", line 350, in match_request
    result = self.url_adapter.match(return_rule=True)
  File "/Users/SanchitBatra/Desktop/Projects/deploybrh/venv/lib/python3.7/site-packages/werkzeug/routing.py", line 1799, in match
    raise NotFound()
werkzeug.exceptions.NotFound: 404 Not Found: The requested URL was not found on the server. If you entered the URL manually please check your spelling and try again.

During handling of the above exception, another exception occurred:

Traceback (most recent call last):
  File "/Users/SanchitBatra/Desktop/Projects/deploybrh/venv/lib/python3.7/site-packages/flask/app.py", line 2446, in wsgi_app
    response = self.full_dispatch_request()
  File "/Users/SanchitBatra/Desktop/Projects/deploybrh/venv/lib/python3.7/site-packages/flask/app.py", line 1951, in full_dispatch_request
    rv = self.handle_user_exception(e)
  File "/Users/SanchitBatra/Desktop/Projects/deploybrh/venv/lib/python3.7/site-packages/flask/app.py", line 1815, in handle_user_exception
    return self.handle_http_exception(e)
  File "/Users/SanchitBatra/Desktop/Projects/deploybrh/venv/lib/python3.7/site-packages/flask/app.py", line 1743, in handle_http_exception
    return handler(e)
  File "/Users/SanchitBatra/Desktop/Projects/deploybrh/app.py", line 251, in not_found_error
    return render_template('errors/404.html'), 404
  File "/Users/SanchitBatra/Desktop/Projects/deploybrh/venv/lib/python3.7/site-packages/flask/templating.py", line 138, in render_template
    ctx.app.jinja_env.get_or_select_template(template_name_or_list),
  File "/Users/SanchitBatra/Desktop/Projects/deploybrh/venv/lib/python3.7/site-packages/jinja2/environment.py", line 869, in get_or_select_template
    return self.get_template(template_name_or_list, parent, globals)
  File "/Users/SanchitBatra/Desktop/Projects/deploybrh/venv/lib/python3.7/site-packages/jinja2/environment.py", line 830, in get_template
    return self._load_template(name, self.make_globals(globals))
  File "/Users/SanchitBatra/Desktop/Projects/deploybrh/venv/lib/python3.7/site-packages/jinja2/environment.py", line 804, in _load_template
    template = self.loader.load(self, name, globals)
  File "/Users/SanchitBatra/Desktop/Projects/deploybrh/venv/lib/python3.7/site-packages/jinja2/loaders.py", line 113, in load
    source, filename, uptodate = self.get_source(environment, name)
  File "/Users/SanchitBatra/Desktop/Projects/deploybrh/venv/lib/python3.7/site-packages/flask/templating.py", line 60, in get_source
    return self._get_source_fast(environment, template)
  File "/Users/SanchitBatra/Desktop/Projects/deploybrh/venv/lib/python3.7/site-packages/flask/templating.py", line 89, in _get_source_fast
    raise TemplateNotFound(template)
jinja2.exceptions.TemplateNotFound: errors/404.html
2019-09-22 07:33:07,284 ERROR: Exception on /favicon.ico [GET] [in /Users/SanchitBatra/Desktop/Projects/deploybrh/venv/lib/python3.7/site-packages/flask/app.py:1891]
Traceback (most recent call last):
  File "/Users/SanchitBatra/Desktop/Projects/deploybrh/venv/lib/python3.7/site-packages/flask/app.py", line 1949, in full_dispatch_request
    rv = self.dispatch_request()
  File "/Users/SanchitBatra/Desktop/Projects/deploybrh/venv/lib/python3.7/site-packages/flask/app.py", line 1925, in dispatch_request
    self.raise_routing_exception(req)
  File "/Users/SanchitBatra/Desktop/Projects/deploybrh/venv/lib/python3.7/site-packages/flask/app.py", line 1907, in raise_routing_exception
    raise request.routing_exception
  File "/Users/SanchitBatra/Desktop/Projects/deploybrh/venv/lib/python3.7/site-packages/flask/ctx.py", line 350, in match_request
    result = self.url_adapter.match(return_rule=True)
  File "/Users/SanchitBatra/Desktop/Projects/deploybrh/venv/lib/python3.7/site-packages/werkzeug/routing.py", line 1799, in match
    raise NotFound()
werkzeug.exceptions.NotFound: 404 Not Found: The requested URL was not found on the server. If you entered the URL manually please check your spelling and try again.

During handling of the above exception, another exception occurred:

Traceback (most recent call last):
  File "/Users/SanchitBatra/Desktop/Projects/deploybrh/venv/lib/python3.7/site-packages/flask/app.py", line 2446, in wsgi_app
    response = self.full_dispatch_request()
  File "/Users/SanchitBatra/Desktop/Projects/deploybrh/venv/lib/python3.7/site-packages/flask/app.py", line 1951, in full_dispatch_request
    rv = self.handle_user_exception(e)
  File "/Users/SanchitBatra/Desktop/Projects/deploybrh/venv/lib/python3.7/site-packages/flask/app.py", line 1815, in handle_user_exception
    return self.handle_http_exception(e)
  File "/Users/SanchitBatra/Desktop/Projects/deploybrh/venv/lib/python3.7/site-packages/flask/app.py", line 1743, in handle_http_exception
    return handler(e)
  File "/Users/SanchitBatra/Desktop/Projects/deploybrh/app.py", line 251, in not_found_error
    return render_template('errors/404.html'), 404
  File "/Users/SanchitBatra/Desktop/Projects/deploybrh/venv/lib/python3.7/site-packages/flask/templating.py", line 138, in render_template
    ctx.app.jinja_env.get_or_select_template(template_name_or_list),
  File "/Users/SanchitBatra/Desktop/Projects/deploybrh/venv/lib/python3.7/site-packages/jinja2/environment.py", line 869, in get_or_select_template
    return self.get_template(template_name_or_list, parent, globals)
  File "/Users/SanchitBatra/Desktop/Projects/deploybrh/venv/lib/python3.7/site-packages/jinja2/environment.py", line 830, in get_template
    return self._load_template(name, self.make_globals(globals))
  File "/Users/SanchitBatra/Desktop/Projects/deploybrh/venv/lib/python3.7/site-packages/jinja2/environment.py", line 804, in _load_template
    template = self.loader.load(self, name, globals)
  File "/Users/SanchitBatra/Desktop/Projects/deploybrh/venv/lib/python3.7/site-packages/jinja2/loaders.py", line 113, in load
    source, filename, uptodate = self.get_source(environment, name)
  File "/Users/SanchitBatra/Desktop/Projects/deploybrh/venv/lib/python3.7/site-packages/flask/templating.py", line 60, in get_source
    return self._get_source_fast(environment, template)
  File "/Users/SanchitBatra/Desktop/Projects/deploybrh/venv/lib/python3.7/site-packages/flask/templating.py", line 89, in _get_source_fast
    raise TemplateNotFound(template)
jinja2.exceptions.TemplateNotFound: errors/404.html
2019-09-22 07:33:08,476 ERROR: Exception on /favicon.ico [GET] [in /Users/SanchitBatra/Desktop/Projects/deploybrh/venv/lib/python3.7/site-packages/flask/app.py:1891]
Traceback (most recent call last):
  File "/Users/SanchitBatra/Desktop/Projects/deploybrh/venv/lib/python3.7/site-packages/flask/app.py", line 1949, in full_dispatch_request
    rv = self.dispatch_request()
  File "/Users/SanchitBatra/Desktop/Projects/deploybrh/venv/lib/python3.7/site-packages/flask/app.py", line 1925, in dispatch_request
    self.raise_routing_exception(req)
  File "/Users/SanchitBatra/Desktop/Projects/deploybrh/venv/lib/python3.7/site-packages/flask/app.py", line 1907, in raise_routing_exception
    raise request.routing_exception
  File "/Users/SanchitBatra/Desktop/Projects/deploybrh/venv/lib/python3.7/site-packages/flask/ctx.py", line 350, in match_request
    result = self.url_adapter.match(return_rule=True)
  File "/Users/SanchitBatra/Desktop/Projects/deploybrh/venv/lib/python3.7/site-packages/werkzeug/routing.py", line 1799, in match
    raise NotFound()
werkzeug.exceptions.NotFound: 404 Not Found: The requested URL was not found on the server. If you entered the URL manually please check your spelling and try again.

During handling of the above exception, another exception occurred:

Traceback (most recent call last):
  File "/Users/SanchitBatra/Desktop/Projects/deploybrh/venv/lib/python3.7/site-packages/flask/app.py", line 2446, in wsgi_app
    response = self.full_dispatch_request()
  File "/Users/SanchitBatra/Desktop/Projects/deploybrh/venv/lib/python3.7/site-packages/flask/app.py", line 1951, in full_dispatch_request
    rv = self.handle_user_exception(e)
  File "/Users/SanchitBatra/Desktop/Projects/deploybrh/venv/lib/python3.7/site-packages/flask/app.py", line 1815, in handle_user_exception
    return self.handle_http_exception(e)
  File "/Users/SanchitBatra/Desktop/Projects/deploybrh/venv/lib/python3.7/site-packages/flask/app.py", line 1743, in handle_http_exception
    return handler(e)
  File "/Users/SanchitBatra/Desktop/Projects/deploybrh/app.py", line 251, in not_found_error
    return render_template('errors/404.html'), 404
  File "/Users/SanchitBatra/Desktop/Projects/deploybrh/venv/lib/python3.7/site-packages/flask/templating.py", line 138, in render_template
    ctx.app.jinja_env.get_or_select_template(template_name_or_list),
  File "/Users/SanchitBatra/Desktop/Projects/deploybrh/venv/lib/python3.7/site-packages/jinja2/environment.py", line 869, in get_or_select_template
    return self.get_template(template_name_or_list, parent, globals)
  File "/Users/SanchitBatra/Desktop/Projects/deploybrh/venv/lib/python3.7/site-packages/jinja2/environment.py", line 830, in get_template
    return self._load_template(name, self.make_globals(globals))
  File "/Users/SanchitBatra/Desktop/Projects/deploybrh/venv/lib/python3.7/site-packages/jinja2/environment.py", line 804, in _load_template
    template = self.loader.load(self, name, globals)
  File "/Users/SanchitBatra/Desktop/Projects/deploybrh/venv/lib/python3.7/site-packages/jinja2/loaders.py", line 113, in load
    source, filename, uptodate = self.get_source(environment, name)
  File "/Users/SanchitBatra/Desktop/Projects/deploybrh/venv/lib/python3.7/site-packages/flask/templating.py", line 60, in get_source
    return self._get_source_fast(environment, template)
  File "/Users/SanchitBatra/Desktop/Projects/deploybrh/venv/lib/python3.7/site-packages/flask/templating.py", line 89, in _get_source_fast
    raise TemplateNotFound(template)
jinja2.exceptions.TemplateNotFound: errors/404.html
2019-09-22 07:33:15,990 ERROR: Exception on /favicon.ico [GET] [in /Users/SanchitBatra/Desktop/Projects/deploybrh/venv/lib/python3.7/site-packages/flask/app.py:1891]
Traceback (most recent call last):
  File "/Users/SanchitBatra/Desktop/Projects/deploybrh/venv/lib/python3.7/site-packages/flask/app.py", line 1949, in full_dispatch_request
    rv = self.dispatch_request()
  File "/Users/SanchitBatra/Desktop/Projects/deploybrh/venv/lib/python3.7/site-packages/flask/app.py", line 1925, in dispatch_request
    self.raise_routing_exception(req)
  File "/Users/SanchitBatra/Desktop/Projects/deploybrh/venv/lib/python3.7/site-packages/flask/app.py", line 1907, in raise_routing_exception
    raise request.routing_exception
  File "/Users/SanchitBatra/Desktop/Projects/deploybrh/venv/lib/python3.7/site-packages/flask/ctx.py", line 350, in match_request
    result = self.url_adapter.match(return_rule=True)
  File "/Users/SanchitBatra/Desktop/Projects/deploybrh/venv/lib/python3.7/site-packages/werkzeug/routing.py", line 1799, in match
    raise NotFound()
werkzeug.exceptions.NotFound: 404 Not Found: The requested URL was not found on the server. If you entered the URL manually please check your spelling and try again.

During handling of the above exception, another exception occurred:

Traceback (most recent call last):
  File "/Users/SanchitBatra/Desktop/Projects/deploybrh/venv/lib/python3.7/site-packages/flask/app.py", line 2446, in wsgi_app
    response = self.full_dispatch_request()
  File "/Users/SanchitBatra/Desktop/Projects/deploybrh/venv/lib/python3.7/site-packages/flask/app.py", line 1951, in full_dispatch_request
    rv = self.handle_user_exception(e)
  File "/Users/SanchitBatra/Desktop/Projects/deploybrh/venv/lib/python3.7/site-packages/flask/app.py", line 1815, in handle_user_exception
    return self.handle_http_exception(e)
  File "/Users/SanchitBatra/Desktop/Projects/deploybrh/venv/lib/python3.7/site-packages/flask/app.py", line 1743, in handle_http_exception
    return handler(e)
  File "/Users/SanchitBatra/Desktop/Projects/deploybrh/app.py", line 251, in not_found_error
    return render_template('errors/404.html'), 404
  File "/Users/SanchitBatra/Desktop/Projects/deploybrh/venv/lib/python3.7/site-packages/flask/templating.py", line 138, in render_template
    ctx.app.jinja_env.get_or_select_template(template_name_or_list),
  File "/Users/SanchitBatra/Desktop/Projects/deploybrh/venv/lib/python3.7/site-packages/jinja2/environment.py", line 869, in get_or_select_template
    return self.get_template(template_name_or_list, parent, globals)
  File "/Users/SanchitBatra/Desktop/Projects/deploybrh/venv/lib/python3.7/site-packages/jinja2/environment.py", line 830, in get_template
    return self._load_template(name, self.make_globals(globals))
  File "/Users/SanchitBatra/Desktop/Projects/deploybrh/venv/lib/python3.7/site-packages/jinja2/environment.py", line 804, in _load_template
    template = self.loader.load(self, name, globals)
  File "/Users/SanchitBatra/Desktop/Projects/deploybrh/venv/lib/python3.7/site-packages/jinja2/loaders.py", line 113, in load
    source, filename, uptodate = self.get_source(environment, name)
  File "/Users/SanchitBatra/Desktop/Projects/deploybrh/venv/lib/python3.7/site-packages/flask/templating.py", line 60, in get_source
    return self._get_source_fast(environment, template)
  File "/Users/SanchitBatra/Desktop/Projects/deploybrh/venv/lib/python3.7/site-packages/flask/templating.py", line 89, in _get_source_fast
    raise TemplateNotFound(template)
jinja2.exceptions.TemplateNotFound: errors/404.html
2019-09-22 07:33:22,875 ERROR: Exception on /favicon.ico [GET] [in /Users/SanchitBatra/Desktop/Projects/deploybrh/venv/lib/python3.7/site-packages/flask/app.py:1891]
Traceback (most recent call last):
  File "/Users/SanchitBatra/Desktop/Projects/deploybrh/venv/lib/python3.7/site-packages/flask/app.py", line 1949, in full_dispatch_request
    rv = self.dispatch_request()
  File "/Users/SanchitBatra/Desktop/Projects/deploybrh/venv/lib/python3.7/site-packages/flask/app.py", line 1925, in dispatch_request
    self.raise_routing_exception(req)
  File "/Users/SanchitBatra/Desktop/Projects/deploybrh/venv/lib/python3.7/site-packages/flask/app.py", line 1907, in raise_routing_exception
    raise request.routing_exception
  File "/Users/SanchitBatra/Desktop/Projects/deploybrh/venv/lib/python3.7/site-packages/flask/ctx.py", line 350, in match_request
    result = self.url_adapter.match(return_rule=True)
  File "/Users/SanchitBatra/Desktop/Projects/deploybrh/venv/lib/python3.7/site-packages/werkzeug/routing.py", line 1799, in match
    raise NotFound()
werkzeug.exceptions.NotFound: 404 Not Found: The requested URL was not found on the server. If you entered the URL manually please check your spelling and try again.

During handling of the above exception, another exception occurred:

Traceback (most recent call last):
  File "/Users/SanchitBatra/Desktop/Projects/deploybrh/venv/lib/python3.7/site-packages/flask/app.py", line 2446, in wsgi_app
    response = self.full_dispatch_request()
  File "/Users/SanchitBatra/Desktop/Projects/deploybrh/venv/lib/python3.7/site-packages/flask/app.py", line 1951, in full_dispatch_request
    rv = self.handle_user_exception(e)
  File "/Users/SanchitBatra/Desktop/Projects/deploybrh/venv/lib/python3.7/site-packages/flask/app.py", line 1815, in handle_user_exception
    return self.handle_http_exception(e)
  File "/Users/SanchitBatra/Desktop/Projects/deploybrh/venv/lib/python3.7/site-packages/flask/app.py", line 1743, in handle_http_exception
    return handler(e)
  File "/Users/SanchitBatra/Desktop/Projects/deploybrh/app.py", line 251, in not_found_error
    return render_template('errors/404.html'), 404
  File "/Users/SanchitBatra/Desktop/Projects/deploybrh/venv/lib/python3.7/site-packages/flask/templating.py", line 138, in render_template
    ctx.app.jinja_env.get_or_select_template(template_name_or_list),
  File "/Users/SanchitBatra/Desktop/Projects/deploybrh/venv/lib/python3.7/site-packages/jinja2/environment.py", line 869, in get_or_select_template
    return self.get_template(template_name_or_list, parent, globals)
  File "/Users/SanchitBatra/Desktop/Projects/deploybrh/venv/lib/python3.7/site-packages/jinja2/environment.py", line 830, in get_template
    return self._load_template(name, self.make_globals(globals))
  File "/Users/SanchitBatra/Desktop/Projects/deploybrh/venv/lib/python3.7/site-packages/jinja2/environment.py", line 804, in _load_template
    template = self.loader.load(self, name, globals)
  File "/Users/SanchitBatra/Desktop/Projects/deploybrh/venv/lib/python3.7/site-packages/jinja2/loaders.py", line 113, in load
    source, filename, uptodate = self.get_source(environment, name)
  File "/Users/SanchitBatra/Desktop/Projects/deploybrh/venv/lib/python3.7/site-packages/flask/templating.py", line 60, in get_source
    return self._get_source_fast(environment, template)
  File "/Users/SanchitBatra/Desktop/Projects/deploybrh/venv/lib/python3.7/site-packages/flask/templating.py", line 89, in _get_source_fast
    raise TemplateNotFound(template)
jinja2.exceptions.TemplateNotFound: errors/404.html
2019-09-22 07:33:27,037 ERROR: Exception on /favicon.ico [GET] [in /Users/SanchitBatra/Desktop/Projects/deploybrh/venv/lib/python3.7/site-packages/flask/app.py:1891]
Traceback (most recent call last):
  File "/Users/SanchitBatra/Desktop/Projects/deploybrh/venv/lib/python3.7/site-packages/flask/app.py", line 1949, in full_dispatch_request
    rv = self.dispatch_request()
  File "/Users/SanchitBatra/Desktop/Projects/deploybrh/venv/lib/python3.7/site-packages/flask/app.py", line 1925, in dispatch_request
    self.raise_routing_exception(req)
  File "/Users/SanchitBatra/Desktop/Projects/deploybrh/venv/lib/python3.7/site-packages/flask/app.py", line 1907, in raise_routing_exception
    raise request.routing_exception
  File "/Users/SanchitBatra/Desktop/Projects/deploybrh/venv/lib/python3.7/site-packages/flask/ctx.py", line 350, in match_request
    result = self.url_adapter.match(return_rule=True)
  File "/Users/SanchitBatra/Desktop/Projects/deploybrh/venv/lib/python3.7/site-packages/werkzeug/routing.py", line 1799, in match
    raise NotFound()
werkzeug.exceptions.NotFound: 404 Not Found: The requested URL was not found on the server. If you entered the URL manually please check your spelling and try again.

During handling of the above exception, another exception occurred:

Traceback (most recent call last):
  File "/Users/SanchitBatra/Desktop/Projects/deploybrh/venv/lib/python3.7/site-packages/flask/app.py", line 2446, in wsgi_app
    response = self.full_dispatch_request()
  File "/Users/SanchitBatra/Desktop/Projects/deploybrh/venv/lib/python3.7/site-packages/flask/app.py", line 1951, in full_dispatch_request
    rv = self.handle_user_exception(e)
  File "/Users/SanchitBatra/Desktop/Projects/deploybrh/venv/lib/python3.7/site-packages/flask/app.py", line 1815, in handle_user_exception
    return self.handle_http_exception(e)
  File "/Users/SanchitBatra/Desktop/Projects/deploybrh/venv/lib/python3.7/site-packages/flask/app.py", line 1743, in handle_http_exception
    return handler(e)
  File "/Users/SanchitBatra/Desktop/Projects/deploybrh/app.py", line 251, in not_found_error
    return render_template('errors/404.html'), 404
  File "/Users/SanchitBatra/Desktop/Projects/deploybrh/venv/lib/python3.7/site-packages/flask/templating.py", line 138, in render_template
    ctx.app.jinja_env.get_or_select_template(template_name_or_list),
  File "/Users/SanchitBatra/Desktop/Projects/deploybrh/venv/lib/python3.7/site-packages/jinja2/environment.py", line 869, in get_or_select_template
    return self.get_template(template_name_or_list, parent, globals)
  File "/Users/SanchitBatra/Desktop/Projects/deploybrh/venv/lib/python3.7/site-packages/jinja2/environment.py", line 830, in get_template
    return self._load_template(name, self.make_globals(globals))
  File "/Users/SanchitBatra/Desktop/Projects/deploybrh/venv/lib/python3.7/site-packages/jinja2/environment.py", line 804, in _load_template
    template = self.loader.load(self, name, globals)
  File "/Users/SanchitBatra/Desktop/Projects/deploybrh/venv/lib/python3.7/site-packages/jinja2/loaders.py", line 113, in load
    source, filename, uptodate = self.get_source(environment, name)
  File "/Users/SanchitBatra/Desktop/Projects/deploybrh/venv/lib/python3.7/site-packages/flask/templating.py", line 60, in get_source
    return self._get_source_fast(environment, template)
  File "/Users/SanchitBatra/Desktop/Projects/deploybrh/venv/lib/python3.7/site-packages/flask/templating.py", line 89, in _get_source_fast
    raise TemplateNotFound(template)
jinja2.exceptions.TemplateNotFound: errors/404.html
2019-09-22 07:33:27,888 ERROR: Exception on /favicon.ico [GET] [in /Users/SanchitBatra/Desktop/Projects/deploybrh/venv/lib/python3.7/site-packages/flask/app.py:1891]
Traceback (most recent call last):
  File "/Users/SanchitBatra/Desktop/Projects/deploybrh/venv/lib/python3.7/site-packages/flask/app.py", line 1949, in full_dispatch_request
    rv = self.dispatch_request()
  File "/Users/SanchitBatra/Desktop/Projects/deploybrh/venv/lib/python3.7/site-packages/flask/app.py", line 1925, in dispatch_request
    self.raise_routing_exception(req)
  File "/Users/SanchitBatra/Desktop/Projects/deploybrh/venv/lib/python3.7/site-packages/flask/app.py", line 1907, in raise_routing_exception
    raise request.routing_exception
  File "/Users/SanchitBatra/Desktop/Projects/deploybrh/venv/lib/python3.7/site-packages/flask/ctx.py", line 350, in match_request
    result = self.url_adapter.match(return_rule=True)
  File "/Users/SanchitBatra/Desktop/Projects/deploybrh/venv/lib/python3.7/site-packages/werkzeug/routing.py", line 1799, in match
    raise NotFound()
werkzeug.exceptions.NotFound: 404 Not Found: The requested URL was not found on the server. If you entered the URL manually please check your spelling and try again.

During handling of the above exception, another exception occurred:

Traceback (most recent call last):
  File "/Users/SanchitBatra/Desktop/Projects/deploybrh/venv/lib/python3.7/site-packages/flask/app.py", line 2446, in wsgi_app
    response = self.full_dispatch_request()
  File "/Users/SanchitBatra/Desktop/Projects/deploybrh/venv/lib/python3.7/site-packages/flask/app.py", line 1951, in full_dispatch_request
    rv = self.handle_user_exception(e)
  File "/Users/SanchitBatra/Desktop/Projects/deploybrh/venv/lib/python3.7/site-packages/flask/app.py", line 1815, in handle_user_exception
    return self.handle_http_exception(e)
  File "/Users/SanchitBatra/Desktop/Projects/deploybrh/venv/lib/python3.7/site-packages/flask/app.py", line 1743, in handle_http_exception
    return handler(e)
  File "/Users/SanchitBatra/Desktop/Projects/deploybrh/app.py", line 251, in not_found_error
    return render_template('errors/404.html'), 404
  File "/Users/SanchitBatra/Desktop/Projects/deploybrh/venv/lib/python3.7/site-packages/flask/templating.py", line 138, in render_template
    ctx.app.jinja_env.get_or_select_template(template_name_or_list),
  File "/Users/SanchitBatra/Desktop/Projects/deploybrh/venv/lib/python3.7/site-packages/jinja2/environment.py", line 869, in get_or_select_template
    return self.get_template(template_name_or_list, parent, globals)
  File "/Users/SanchitBatra/Desktop/Projects/deploybrh/venv/lib/python3.7/site-packages/jinja2/environment.py", line 830, in get_template
    return self._load_template(name, self.make_globals(globals))
  File "/Users/SanchitBatra/Desktop/Projects/deploybrh/venv/lib/python3.7/site-packages/jinja2/environment.py", line 804, in _load_template
    template = self.loader.load(self, name, globals)
  File "/Users/SanchitBatra/Desktop/Projects/deploybrh/venv/lib/python3.7/site-packages/jinja2/loaders.py", line 113, in load
    source, filename, uptodate = self.get_source(environment, name)
  File "/Users/SanchitBatra/Desktop/Projects/deploybrh/venv/lib/python3.7/site-packages/flask/templating.py", line 60, in get_source
    return self._get_source_fast(environment, template)
  File "/Users/SanchitBatra/Desktop/Projects/deploybrh/venv/lib/python3.7/site-packages/flask/templating.py", line 89, in _get_source_fast
    raise TemplateNotFound(template)
jinja2.exceptions.TemplateNotFound: errors/404.html
2019-09-22 07:33:34,736 ERROR: Exception on /address/ [GET] [in /Users/SanchitBatra/Desktop/Projects/deploybrh/venv/lib/python3.7/site-packages/flask/app.py:1891]
Traceback (most recent call last):
  File "/Users/SanchitBatra/Desktop/Projects/deploybrh/venv/lib/python3.7/site-packages/flask/app.py", line 2446, in wsgi_app
    response = self.full_dispatch_request()
  File "/Users/SanchitBatra/Desktop/Projects/deploybrh/venv/lib/python3.7/site-packages/flask/app.py", line 1951, in full_dispatch_request
    rv = self.handle_user_exception(e)
  File "/Users/SanchitBatra/Desktop/Projects/deploybrh/venv/lib/python3.7/site-packages/flask/app.py", line 1820, in handle_user_exception
    reraise(exc_type, exc_value, tb)
  File "/Users/SanchitBatra/Desktop/Projects/deploybrh/venv/lib/python3.7/site-packages/flask/_compat.py", line 39, in reraise
    raise value
  File "/Users/SanchitBatra/Desktop/Projects/deploybrh/venv/lib/python3.7/site-packages/flask/app.py", line 1949, in full_dispatch_request
    rv = self.dispatch_request()
  File "/Users/SanchitBatra/Desktop/Projects/deploybrh/venv/lib/python3.7/site-packages/flask/app.py", line 1935, in dispatch_request
    return self.view_functions[rule.endpoint](**req.view_args)
  File "/Users/SanchitBatra/Desktop/Projects/deploybrh/app.py", line 195, in process_address
    "price": locale.currency(price[1], grouping=True)
  File "/Users/SanchitBatra/Desktop/Projects/deploybrh/venv/lib/python3.7/locale.py", line 270, in currency
    s = _format('%%.%if' % digits, abs(val), grouping, monetary=True)
TypeError: bad operand type for abs(): 'str'
2019-09-22 07:33:34,937 ERROR: Exception on /favicon.ico [GET] [in /Users/SanchitBatra/Desktop/Projects/deploybrh/venv/lib/python3.7/site-packages/flask/app.py:1891]
Traceback (most recent call last):
  File "/Users/SanchitBatra/Desktop/Projects/deploybrh/venv/lib/python3.7/site-packages/flask/app.py", line 1949, in full_dispatch_request
    rv = self.dispatch_request()
  File "/Users/SanchitBatra/Desktop/Projects/deploybrh/venv/lib/python3.7/site-packages/flask/app.py", line 1925, in dispatch_request
    self.raise_routing_exception(req)
  File "/Users/SanchitBatra/Desktop/Projects/deploybrh/venv/lib/python3.7/site-packages/flask/app.py", line 1907, in raise_routing_exception
    raise request.routing_exception
  File "/Users/SanchitBatra/Desktop/Projects/deploybrh/venv/lib/python3.7/site-packages/flask/ctx.py", line 350, in match_request
    result = self.url_adapter.match(return_rule=True)
  File "/Users/SanchitBatra/Desktop/Projects/deploybrh/venv/lib/python3.7/site-packages/werkzeug/routing.py", line 1799, in match
    raise NotFound()
werkzeug.exceptions.NotFound: 404 Not Found: The requested URL was not found on the server. If you entered the URL manually please check your spelling and try again.

During handling of the above exception, another exception occurred:

Traceback (most recent call last):
  File "/Users/SanchitBatra/Desktop/Projects/deploybrh/venv/lib/python3.7/site-packages/flask/app.py", line 2446, in wsgi_app
    response = self.full_dispatch_request()
  File "/Users/SanchitBatra/Desktop/Projects/deploybrh/venv/lib/python3.7/site-packages/flask/app.py", line 1951, in full_dispatch_request
    rv = self.handle_user_exception(e)
  File "/Users/SanchitBatra/Desktop/Projects/deploybrh/venv/lib/python3.7/site-packages/flask/app.py", line 1815, in handle_user_exception
    return self.handle_http_exception(e)
  File "/Users/SanchitBatra/Desktop/Projects/deploybrh/venv/lib/python3.7/site-packages/flask/app.py", line 1743, in handle_http_exception
    return handler(e)
  File "/Users/SanchitBatra/Desktop/Projects/deploybrh/app.py", line 251, in not_found_error
    return render_template('errors/404.html'), 404
  File "/Users/SanchitBatra/Desktop/Projects/deploybrh/venv/lib/python3.7/site-packages/flask/templating.py", line 138, in render_template
    ctx.app.jinja_env.get_or_select_template(template_name_or_list),
  File "/Users/SanchitBatra/Desktop/Projects/deploybrh/venv/lib/python3.7/site-packages/jinja2/environment.py", line 869, in get_or_select_template
    return self.get_template(template_name_or_list, parent, globals)
  File "/Users/SanchitBatra/Desktop/Projects/deploybrh/venv/lib/python3.7/site-packages/jinja2/environment.py", line 830, in get_template
    return self._load_template(name, self.make_globals(globals))
  File "/Users/SanchitBatra/Desktop/Projects/deploybrh/venv/lib/python3.7/site-packages/jinja2/environment.py", line 804, in _load_template
    template = self.loader.load(self, name, globals)
  File "/Users/SanchitBatra/Desktop/Projects/deploybrh/venv/lib/python3.7/site-packages/jinja2/loaders.py", line 113, in load
    source, filename, uptodate = self.get_source(environment, name)
  File "/Users/SanchitBatra/Desktop/Projects/deploybrh/venv/lib/python3.7/site-packages/flask/templating.py", line 60, in get_source
    return self._get_source_fast(environment, template)
  File "/Users/SanchitBatra/Desktop/Projects/deploybrh/venv/lib/python3.7/site-packages/flask/templating.py", line 89, in _get_source_fast
    raise TemplateNotFound(template)
jinja2.exceptions.TemplateNotFound: errors/404.html
2019-09-22 07:34:20,716 INFO: errors [in /Users/SanchitBatra/Desktop/Projects/deploybrh/app.py:254]
2019-09-22 07:34:25,060 ERROR: Exception on /address/ [GET] [in /Users/SanchitBatra/Desktop/Projects/deploybrh/venv/lib/python3.7/site-packages/flask/app.py:1891]
Traceback (most recent call last):
  File "/Users/SanchitBatra/Desktop/Projects/deploybrh/venv/lib/python3.7/site-packages/flask/app.py", line 2446, in wsgi_app
    response = self.full_dispatch_request()
  File "/Users/SanchitBatra/Desktop/Projects/deploybrh/venv/lib/python3.7/site-packages/flask/app.py", line 1951, in full_dispatch_request
    rv = self.handle_user_exception(e)
  File "/Users/SanchitBatra/Desktop/Projects/deploybrh/venv/lib/python3.7/site-packages/flask/app.py", line 1820, in handle_user_exception
    reraise(exc_type, exc_value, tb)
  File "/Users/SanchitBatra/Desktop/Projects/deploybrh/venv/lib/python3.7/site-packages/flask/_compat.py", line 39, in reraise
    raise value
  File "/Users/SanchitBatra/Desktop/Projects/deploybrh/venv/lib/python3.7/site-packages/flask/app.py", line 1949, in full_dispatch_request
    rv = self.dispatch_request()
  File "/Users/SanchitBatra/Desktop/Projects/deploybrh/venv/lib/python3.7/site-packages/flask/app.py", line 1935, in dispatch_request
    return self.view_functions[rule.endpoint](**req.view_args)
  File "/Users/SanchitBatra/Desktop/Projects/deploybrh/app.py", line 195, in process_address
    "price": locale.currency(price[1], grouping=True)
  File "/Users/SanchitBatra/Desktop/Projects/deploybrh/venv/lib/python3.7/locale.py", line 270, in currency
    s = _format('%%.%if' % digits, abs(val), grouping, monetary=True)
TypeError: bad operand type for abs(): 'str'
2019-09-22 07:36:06,992 INFO: errors [in /Users/SanchitBatra/Desktop/Projects/deploybrh/app.py:254]
2019-09-22 07:37:28,219 INFO: errors [in /Users/SanchitBatra/Desktop/Projects/deploybrh/app.py:254]
